<?xml version="1.0"?>
<robot name="arm1" xmlns:xacro="http://ros.org/wiki/xacro">
<link name="world"/>


<link name="base_link">
<visual>
<geometry>
    <mesh filename="package://siro_arm/models/meshes/visual/Ensamble_1.stl"/>
  </geometry>
</visual> 

</link>

<link name="link_1">
<visual>
<geometry>
    <mesh filename="package://siro_arm/models/meshes/visual/Ensamble_2.stl"/>
  </geometry>
</visual> 

</link>




<joint name="fixed" type="fixed">
    <parent link="world"/>
    <child link="base_link"/>
</joint>

<joint name="joint_1" type="revolute">
<parent link="base_link"/>
<child link="link_1"/>
<origin xyz="0 0 5" rpy="0 0 0"/>
<axis xyz="0 0 1"/>
<limit lower="-1.57" upper="1.57" effort="0" velocity="0.5"/>
</joint>


  <gazebo reference="camera_link">
    <sensor name="depth_camera" type="depth">
      <visualize>true</visualize>
      <update_rate>30.0</update_rate>
      <camera name="camera">
        <horizontal_fov>1.047198</horizontal_fov>
        <image>
          <width>640</width>
          <height>480</height>
          <format>R8G8B8</format>
        </image>
        <clip>
          <near>0.05</near>
          <far>3</far>
        </clip>
      </camera>
      <plugin name="depth_camera_controller" filename="libgazebo_ros_camera.so">
        <baseline>0.2</baseline>
        <alwaysOn>true</alwaysOn>
        <updateRate>0.0</updateRate>
        <frame_name>camera_depth_frame</frame_name>
        <pointCloudCutoff>0.5</pointCloudCutoff>
        <pointCloudCutoffMax>3.0</pointCloudCutoffMax>
        <distortionK1>0</distortionK1>
        <distortionK2>0</distortionK2>
        <distortionK3>0</distortionK3>
        <distortionT1>0</distortionT1>
        <distortionT2>0</distortionT2>
        <CxPrime>0</CxPrime>
        <Cx>0</Cx>
        <Cy>0</Cy>
        <focalLength>0</focalLength>
        <hackBaseline>0</hackBaseline>
      </plugin>
    </sensor>

    <sensor name="my_camera_sensor" update_rate="20">
      <parent link="optical_frame_link_name"/>
      <origin xyz="0 0 0" rpy="0 0 0"/>
      <camera>
        <image width="640" height="480" hfov="1.5708" format="RGB8" near="0.01" far="50.0"/>
      </camera>
    </sensor>

  </gazebo>



</robot>